---
identifier: "CVE-2019-16249"
identifiers:
- "GHSA-x3rm-644h-67m8"
- "CVE-2019-16249"
package_slug: "pypi/opencv-python-headless"
title: "Out-of-bounds Read"
description: "OpenCV has an out-of-bounds read in hal_baseline::v_load in core/hal/intrin_sse.hpp
  when called from computeSSDMeanNorm in modules/video/src/dis_flow.cpp."
date: "2021-10-12"
pubdate: "2021-10-12"
affected_range: "<=4.1.1.26"
fixed_versions:
- "4.1.2.30"
affected_versions: "All versions up to 4.1.1.26"
not_impacted: "All versions after 4.1.1.26"
solution: "Upgrade to version 4.1.2.30 or above."
urls:
- "https://nvd.nist.gov/vuln/detail/CVE-2019-16249"
- "https://github.com/opencv/opencv/issues/15481"
- "https://github.com/opencv/opencv/pull/15531"
- "https://bugzilla.redhat.com/show_bug.cgi?id=1752702"
- "https://github.com/opencv/opencv-python/releases/tag/30"
- "https://github.com/advisories/GHSA-x3rm-644h-67m8"
cvss_v2: "AV:N/AC:L/Au:N/C:P/I:N/A:N"
cvss_v3: "CVSS:3.1/AV:N/AC:L/PR:N/UI:N/S:U/C:L/I:N/A:N"
uuid: "192f5787-5485-4fbe-ac8f-aaa250bccb62"
cwe_ids:
- "CWE-1035"
- "CWE-125"
- "CWE-937"
