---
identifier: "CVE-2019-14491"
identifiers:
- "GHSA-fm39-cw8h-3p63"
- "CVE-2019-14491"
package_slug: "pypi/opencv-python"
title: "Out-of-bounds Read"
description: "An issue was discovered in OpenCV There is an out-of-bounds read in
  the function cv::predictOrdered<cv::HaarEvaluator> in modules/objdetect/src/cascadedetect.hpp,
  which leads to denial of service."
date: "2021-10-12"
pubdate: "2021-10-12"
affected_range: "<=3.4.6.27||>=4.0.0.21,<=4.1.0.25"
fixed_versions:
- "3.4.7.28"
- "4.1.1.26"
affected_versions: "All versions up to 3.4.6.27, all versions starting from 4.0.0.21
  up to 4.1.0.25"
not_impacted: "All versions after 3.4.6.27 before 4.0.0.21, all versions after 4.1.0.25"
solution: "Upgrade to versions 3.4.7.28, 4.1.1.26 or above."
urls:
- "https://nvd.nist.gov/vuln/detail/CVE-2019-14491"
- "https://github.com/opencv/opencv/issues/15125"
- "https://github.com/opencv/opencv/compare/33b765d...4a7ca5a"
- "https://github.com/opencv/opencv/compare/371bba8...ddbd10c"
- "https://lists.fedoraproject.org/archives/list/package-announce@lists.fedoraproject.org/message/HPFLN6QAX6SUA4XR4NMKKXX26H3TYCVQ/"
- "https://github.com/advisories/GHSA-fm39-cw8h-3p63"
cvss_v2: "AV:N/AC:L/Au:N/C:P/I:N/A:P"
cvss_v3: "CVSS:3.0/AV:N/AC:L/PR:N/UI:N/S:U/C:L/I:N/A:H"
uuid: "e4eae38e-0811-479d-881d-70fd410c981c"
cwe_ids:
- "CWE-1035"
- "CWE-125"
- "CWE-937"
